Workbook

Sheet Portada
B2: IPIP-NEO-120
B5: Inventario de Personalidad — Cinco Grandes (Big Five)
B7: Versión bilingüe · autoscoring · dominio público
B11: Estructura
B12: 120 ítems | C12: Escala Likert de 1 a 5 (~15 minutos)
B13: 5 dominios | C13: Neuroticismo, Extraversión, Apertura, Amabilidad, Responsabilidad
B14: 30 facetas | C14: 6 facetas por dominio · 4 ítems por faceta
B15: Normas | C15: Sexo (M/F) × 4 rangos de edad (10-20, 21-40, 41-60, 61-95)
B16: Puntuaciones T | C16: Media 50 · Desviación estándar 10
B18: Empezar
B19: 1 | C19: Abre la hoja "Test", ingresa Sexo y Edad en las celdas amarillas.
B20: 2 | C20: Responde cada ítem con un número del 1 al 5 en la columna "Respuesta".
B21: 3 | C21: Sigue tu progreso en el contador arriba de la hoja "Test".
B22: 4 | C22: Al terminar, revisa "Resultados", "Perfil", "Dominios" y "Facetas".
B25: Ítems IPIP (dominio público) · Selección Johnson (2014) · Traducción ES no oficial
B26: Instrumento autoinformado — NO reemplaza evaluación clínica profesional.

Sheet Instrucciones
B2: Instrucciones
B4: ¿Qué es este cuestionario?
B5: IPIP-NEO-120 es un inventario de personalidad de 120 ítems basado en el modelo de los Cinco Grandes.
B6: Mide 5 dominios (Neuroticismo, Extraversión, Apertura, Amabilidad, Responsabilidad),
B7: cada uno con 6 facetas = 30 facetas × 4 ítems = 120 ítems totales. Duración estimada: ~15 minutos.
B8: Autor: John A. Johnson (2014). Ítems del International Personality Item Pool (IPIP, ipip.ori.org).
B10: Cómo responder
B11: 1. Ve a la hoja "Test".
B12: 2. Ingresa tu Sexo (M/F) y Edad en las celdas amarillas.
B13: 3. Para cada ítem, escribe un número del 1 al 5 en la columna "Respuesta":
B14: 1 = Muy inexacto 2 = Moderadamente inexacto
B15: 3 = Ni inexacto ni exacto 4 = Moderadamente exacto
... B40: Los resultados reflejan una fotografía puntual: pueden variar según ánimo, contexto y momento vital.

Sheet Test
A1: Nombre / Name: | B1: Ivan | C1: =("Respondidas: " & COUNT(E6:E125) & " / 120")
A2: Sexo (M/F): | B2: M | C2: Escala Likert: | D2: 1 · Muy inexacto | E2: 2 · Moderadamente inexacto | F2: 3 · Ni inexacto ni exacto
A3: Edad / Age: | B3: 33 | D3: 4 · Moderadamente exacto | E3: 5 · Muy exacto
A4: Fecha / Date:
A5: # | B5: Faceta | C5: English (original) | D5: Español (no oficial) | E5: Respuesta | F5: Clave | G5: Puntuado
A6: 1 | B6: N1 | C6: Worry about things | D6: Me preocupo por las cosas. | F6: F | G6: =IF(E6="","",IF(F6="F",E6,6-E6))
A7: 2 | B7: E1 | C7: Make friends easily | D7: Hago amigos con facilidad. | F7: F | G7: =IF(E7="","",IF(F7="F",E7,6-E7))
A8: 3 | B8: O1 | C8: Have a vivid imagination | D8: Tengo una imaginación vívida. | F8: F | G8: =IF(E8="","",IF(F8="F",E8,6-E8))
A9: 4 | B9: A1 | C9: Trust others | D9: Confío en los demás. | F9: F | G9: =IF(E9="","",IF(F9="F",E9,6-E9))
A10: 5 | B10: C1 | C10: Complete tasks successfully | D10: Completo las tareas con éxito. | F10: F | G10: =IF(E10="","",IF(F10="F",E10,6-E10))
A11: 6 | B11: N2 | C11: Get angry easily | D11: Me enojo con facilidad. | F11: F | G11: =IF(E11="","",IF(F11="F",E11,6-E11))
A12: 7 | B12: E2 | C12: Love large parties | D12: Me encantan las fiestas grandes. | F12: F | G12: =IF(E12="","",IF(F12="F",E12,6-E12))
A13: 8 | B13: O2 | C13: Believe in the importance of art | D13: Creo en la importancia del arte. | F13: F | G13: =IF(E13="","",IF(F13="F",E13,6-E13))
A14: 9 | B14: A2 | C14: Use others for my own ends | D14: Uso a los demás para mis propios fines. | F14: R | G14: =IF(E14="","",IF(F14="F",E14,6-E14))
A15: 10 | B15: C2 | C15: Like to tidy up | D15: Me gusta ordenar. | F15: F | G15: =IF(E15="","",IF(F15="F",E15,6-E15))
A16: 11 | B16: N3 | C16: Often feel blue | D16: Me siento triste con frecuencia. | F16: F | G16: =IF(E16="","",IF(F16="F",E16,6-E16))
A17: 12 | B17: E3 | C17: Take charge | D17: Tomo el mando. | F17: F | G17: =IF(E17="","",IF(F17="F",E17,6-E17))
... A125: 120 | B125: C6 | C125: Act without thinking | D125: Actúo sin pensar. | F125: R | G125: =IF(E125="","",IF(F125="F",E125,6-E125))

Sheet Normas
A1: Tablas de normas — Johnson (2014)
A2: Media y desviación estándar por grupo Sexo × Edad · 30 facetas + 5 dominios
A3: Escala | B3: M_10-20 media | C3: M_10-20 DE | D3: M_21-40 media | E3: M_21-40 DE | F3: M_41-60 media | G3: M_41-60 DE | H3: M_61-95 media | I3: M_61-95 DE | J3: F_10-20 media | K3: F_10-20 DE | L3: F_21-40 media | M3: F_21-40 DE | N3: F_41-60 media | O3: F_41-60 DE | P3: F_61-95 media | Q3: F_61-95 DE
A4: N1 | B4: 11.673 | C4: 3.754 | D4: 11.381 | E4: 3.791 | F4: 10.653 | G4: 3.591 | H4: 10.706 | I4: 4.342 | J4: 13.352 | K4: 3.657 | L4: 13.167 | M4: 3.706 | N4: 12.038 | O4: 3.745 | P4: 11.78 | Q4: 3.933
A5: N2 | B5: 11.862 | C5: 4.428 | D5: 11.7 | E5: 4.328 | F5: 11.586 | G5: 4.155 | H5: 12.04 | I5: 4.686 | J5: 13.093 | K5: 4.184 | L5: 12.767 | M5: 4.14 | N5: 11.214 | O5: 4.057 | P5: 10.99 | Q5: 3.952
A6: N3 | B6: 10.529 | C6: 4.231 | D6: 10.357 | E6: 4.123 | F6: 9.675 | G6: 3.894 | H6: 8.308 | I6: 4.3 | J6: 11.1 | K6: 4.19 | L6: 10.822 | M6: 4.083 | N6: 10.152 | O6: 4.036 | P6: 9.1 | Q6: 3.773
A7: N4 | B7: 12.386 | C7: 3.819 | D7: 12.028 | E7: 3.827 | F7: 11.675 | G7: 3.668 | H7: 11.62 | I7: 4.213 | J7: 12.208 | K7: 3.839 | L7: 12.243 | M7: 3.809 | N7: 12.055 | O7: 3.765 | P7: 12.03 | Q7: 3.878
A8: N5 | B8: 11.626 | C8: 3.263 | D8: 12.184 | E8: 3.532 | F8: 11.282 | G8: 3.601 | H8: 10.64 | I8: 3.613 | J8: 12.435 | K8: 3.333 | L8: 12.762 | M8: 3.604 | N8: 11.979 | O8: 3.796 | P8: 10.029 | Q8: 3.679
A9: N6 | B9: 9.568 | C9: 3.352 | D9: 9.024 | E9: 3.529 | F9: 8.603 | G9: 3.397 | H9: 9.49 | I9: 4.291 | J9: 11.286 | K9: 3.498 | L9: 10.751 | M9: 3.672 | N9: 10.155 | O9: 3.614 | P9: 10.21 | Q9: 3.655
A10: E1 | B10: 13.751 | C10: 3.785 | D10: 13.376 | E10: 3.846 | F10: 13.37 | G10: 3.734 | H10: 14.327 | I10: 3.974 | J10: 14.395 | K10: 3.648 | L10: 14.032 | M10: 3.692 | N10: 14.191 | O10: 3.758 | P10: 14.794 | Q10: 3.616
A11: E2 | B11: 12.236 | C11: 4.166 | D11: 11.402 | E11: 4.049 | F11: 10.517 | G11: 3.721 | H11: 11 | I11: 3.768 | J11: 12.991 | K11: 4.167 | L11: 11.9 | M11: 4.091 | N11: 10.785 | O11: 3.876 | P11: 10.257 | Q11: 3.738
A12: E3 | B12: 14.074 | C12: 3.675 | D12: 14.706 | E12: 3.59 | F12: 14.993 | G12: 3.552 | H12: 14.647 | I12: 3.851 | J12: 13.974 | K12: 3.691 | L12: 14.198 | M12: 3.638 | N12: 14.441 | O12: 3.578 | P12: 14.31 | Q12: 3.703
A13: E4 | B13: 11.644 | C13: 3.133 | D13: 12.149 | E13: 3.246 | F13: 12.403 | G13: 3.265 | H13: 13.216 | I13: 3.152 | J13: 12.728 | K13: 3.114 | L13: 12.825 | M13: 3.267 | N13: 13.089 | O13: 3.545 | P13: 12.357 | Q13: 3.573
A14: E5 | B14: 14.6 | C14: 3.412 | D14: 13.382 | E14: 3.475 | F14: 11.83 | G14: 3.286 | H14: 11.766 | I14: 3.122 | J14: 14.544 | K14: 3.488 | L14: 12.87 | M14: 3.533 | N14: 11.067 | O14: 3.457 | P14: 9.99 | Q14: 3.252
A15: E6 | B15: 14.36 | C15: 3.672 | D15: 14.279 | E15: 3.576 | F15: 14.429 | G15: 3.276 | H15: 14.347 | I15: 3.672 | J15: 15.296 | K15: 3.462 | L15: 14.982 | M15: 3.311 | N15: 14.941 | O15: 3.345 | P15: 15.929 | Q15: 3.114
... A38: C | B38: 80.13 | C38: 14.674 | D38: 85.758 | E38: 14.279 | F38: 91.306 | G38: 13.118 | H38: 90.837 | I38: 17.518 | J38: 81.742 | K38: 14.295 | L38: 87.504 | M38: 13.941 | N38: 93.214 | O38: 13.39 | P38: 96.121 | Q38: 13.543

Sheet Resultados
A1: Resultados
A3: Grupo normativo: | B3: =Test!B2 & "_" & IF(Test!B3<=20,"10-20",IF(Test!B3<=40,"21-40",IF(Test!B3<=60,"41-60","61-95"))) | C3: (se recalcula al cambiar Sexo/Edad en la hoja Test)
A4: Ítems respondidos: | B4: =COUNT(Test!E6:E125) & " / 120" | C4: (completa los 120 antes de interpretar)
A5: Índice de columna: | B5: =MATCH(B3 & " media", Normas!$B$3:$Q$3, 0)
A7: Código | B7: Nombre EN | C7: Nombre ES | D7: Bruto | E7: Media | F7: DE | G7: T | H7: Nivel
A8: DOMINIOS
A9: N | B9: Neuroticism | C9: Neuroticismo | D9: =SUMPRODUCT((LEFT(Test!$B$6:$B$125,1)="N")*IFERROR(VALUE(Test!$G$6:$G$125),0)) | E9: =INDEX(Normas!$B$4:$Q$38, MATCH(A9, Normas!$A$4:$A$38, 0), $B$5) | F9: =INDEX(Normas!$B$4:$Q$38, MATCH(A9, Normas!$A$4:$A$38, 0), $B$5+1) | G9: =IF(F9=0,"",ROUND(50 + 10 * (D9 - E9) / F9, 0)) | H9: =IF(G9="","",IF(G9<35,"Muy bajo",IF(G9<45,"Bajo",IF(G9<=55,"Promedio",IF(G9<=65,"Alto","Muy alto")))))
A10: E | B10: Extraversion | C10: Extraversión | D10: =SUMPRODUCT((LEFT(Test!$B$6:$B$125,1)="E")*IFERROR(VALUE(Test!$G$6:$G$125),0)) | E10: =INDEX(Normas!$B$4:$Q$38, MATCH(A10, Normas!$A$4:$A$38, 0), $B$5) | F10: =INDEX(Normas!$B$4:$Q$38, MATCH(A10, Normas!$A$4:$A$38, 0), $B$5+1) | G10: =IF(F10=0,"",ROUND(50 + 10 * (D10 - E10) / F10, 0)) | H10: =IF(G10="","",IF(G10<35,"Muy bajo",IF(G10<45,"Bajo",IF(G10<=55,"Promedio",IF(G10<=65,"Alto","Muy alto")))))
A11: O | B11: Openness | C11: Apertura | D11: =SUMPRODUCT((LEFT(Test!$B$6:$B$125,1)="O")*IFERROR(VALUE(Test!$G$6:$G$125),0)) | E11: =INDEX(Normas!$B$4:$Q$38, MATCH(A11, Normas!$A$4:$A$38, 0), $B$5) | F11: =INDEX(Normas!$B$4:$Q$38, MATCH(A11, Normas!$A$4:$A$38, 0), $B$5+1) | G11: =IF(F11=0,"",ROUND(50 + 10 * (D11 - E11) / F11, 0)) | H11: =IF(G11="","",IF(G11<35,"Muy bajo",IF(G11<45,"Bajo",IF(G11<=55,"Promedio",IF(G11<=65,"Alto","Muy alto")))))
A12: A | B12: Agreeableness | C12: Amabilidad | D12: =SUMPRODUCT((LEFT(Test!$B$6:$B$125,1)="A")*IFERROR(VALUE(Test!$G$6:$G$125),0)) | E12: =INDEX(Normas!$B$4:$Q$38, MATCH(A12, Normas!$A$4:$A$38, 0), $B$5) | F12: =INDEX(Normas!$B$4:$Q$38, MATCH(A12, Normas!$A$4:$A$38, 0), $B$5+1) | G12: =IF(F12=0,"",ROUND(50 + 10 * (D12 - E12) / F12, 0)) | H12: =IF(G12="","",IF(G12<35,"Muy bajo",IF(G12<45,"Bajo",IF(G12<=55,"Promedio",IF(G12<=65,"Alto","Muy alto")))))
A13: C | B13: Conscientiousness | C13: Responsabilidad | D13: =SUMPRODUCT((LEFT(Test!$B$6:$B$125,1)="C")*IFERROR(VALUE(Test!$G$6:$G$125),0)) | E13: =INDEX(Normas!$B$4:$Q$38, MATCH(A13, Normas!$A$4:$A$38, 0), $B$5) | F13: =INDEX(Normas!$B$4:$Q$38, MATCH(A13, Normas!$A$4:$A$38, 0), $B$5+1) | G13: =IF(F13=0,"",ROUND(50 + 10 * (D13 - E13) / F13, 0)) | H13: =IF(G13="","",IF(G13<35,"Muy bajo",IF(G13<45,"Bajo",IF(G13<=55,"Promedio",IF(G13<=65,"Alto","Muy alto")))))
A15: FACETAS
A16: N1 | B16: Anxiety | C16: Ansiedad | D16: =SUMPRODUCT((Test!$B$6:$B$125="N1")*IFERROR(VALUE(Test!$G$6:$G$125),0)) | E16: =INDEX(Normas!$B$4:$Q$38, MATCH(A16, Normas!$A$4:$A$38, 0), $B$5) | F16: =INDEX(Normas!$B$4:$Q$38, MATCH(A16, Normas!$A$4:$A$38, 0), $B$5+1) | G16: =IF(F16=0,"",ROUND(50 + 10 * (D16 - E16) / F16, 0)) | H16: =IF(G16="","",IF(G16<35,"Muy bajo",IF(G16<45,"Bajo",IF(G16<=55,"Promedio",IF(G16<=65,"Alto","Muy alto")))))
A17: N2 | B17: Anger | C17: Ira | D17: =SUMPRODUCT((Test!$B$6:$B$125="N2")*IFERROR(VALUE(Test!$G$6:$G$125),0)) | E17: =INDEX(Normas!$B$4:$Q$38, MATCH(A17, Normas!$A$4:$A$38, 0), $B$5) | F17: =INDEX(Normas!$B$4:$Q$38, MATCH(A17, Normas!$A$4:$A$38, 0), $B$5+1) | G17: =IF(F17=0,"",ROUND(50 + 10 * (D17 - E17) / F17, 0)) | H17: =IF(G17="","",IF(G17<35,"Muy bajo",IF(G17<45,"Bajo",IF(G17<=55,"Promedio",IF(G17<=65,"Alto","Muy alto")))))
A18: N3 | B18: Depression | C18: Depresión | D18: =SUMPRODUCT((Test!$B$6:$B$125="N3")*IFERROR(VALUE(Test!$G$6:$G$125),0)) | E18: =INDEX(Normas!$B$4:$Q$38, MATCH(A18, Normas!$A$4:$A$38, 0), $B$5) | F18: =INDEX(Normas!$B$4:$Q$38, MATCH(A18, Normas!$A$4:$A$38, 0), $B$5+1) | G18: =IF(F18=0,"",ROUND(50 + 10 * (D18 - E18) / F18, 0)) | H18: =IF(G18="","",IF(G18<35,"Muy bajo",IF(G18<45,"Bajo",IF(G18<=55,"Promedio",IF(G18<=65,"Alto","Muy alto")))))
A19: N4 | B19: Self-consciousness | C19: Autoconciencia | D19: =SUMPRODUCT((Test!$B$6:$B$125="N4")*IFERROR(VALUE(Test!$G$6:$G$125),0)) | E19: =INDEX(Normas!$B$4:$Q$38, MATCH(A19, Normas!$A$4:$A$38, 0), $B$5) | F19: =INDEX(Normas!$B$4:$Q$38, MATCH(A19, Normas!$A$4:$A$38, 0), $B$5+1) | G19: =IF(F19=0,"",ROUND(50 + 10 * (D19 - E19) / F19, 0)) | H19: =IF(G19="","",IF(G19<35,"Muy bajo",IF(G19<45,"Bajo",IF(G19<=55,"Promedio",IF(G19<=65,"Alto","Muy alto")))))
A20: N5 | B20: Immoderation | C20: Inmoderación | D20: =SUMPRODUCT((Test!$B$6:$B$125="N5")*IFERROR(VALUE(Test!$G$6:$G$125),0)) | E20: =INDEX(Normas!$B$4:$Q$38, MATCH(A20, Normas!$A$4:$A$38, 0), $B$5) | F20: =INDEX(Normas!$B$4:$Q$38, MATCH(A20, Normas!$A$4:$A$38, 0), $B$5+1) | G20: =IF(F20=0,"",ROUND(50 + 10 * (D20 - E20) / F20, 0)) | H20: =IF(G20="","",IF(G20<35,"Muy bajo",IF(G20<45,"Bajo",IF(G20<=55,"Promedio",IF(G20<=65,"Alto","Muy alto")))))
A21: N6 | B21: Vulnerability | C21: Vulnerabilidad | D21: =SUMPRODUCT((Test!$B$6:$B$125="N6")*IFERROR(VALUE(Test!$G$6:$G$125),0)) | E21: =INDEX(Normas!$B$4:$Q$38, MATCH(A21, Normas!$A$4:$A$38, 0), $B$5) | F21: =INDEX(Normas!$B$4:$Q$38, MATCH(A21, Normas!$A$4:$A$38, 0), $B$5+1) | G21: =IF(F21=0,"",ROUND(50 + 10 * (D21 - E21) / F21, 0)) | H21: =IF(G21="","",IF(G21<35,"Muy bajo",IF(G21<45,"Bajo",IF(G21<=55,"Promedio",IF(G21<=65,"Alto","Muy alto")))))
A22: E1 | B22: Friendliness | C22: Amabilidad social | D22: =SUMPRODUCT((Test!$B$6:$B$125="E1")*IFERROR(VALUE(Test!$G$6:$G$125),0)) | E22: =INDEX(Normas!$B$4:$Q$38, MATCH(A22, Normas!$A$4:$A$38, 0), $B$5) | F22: =INDEX(Normas!$B$4:$Q$38, MATCH(A22, Normas!$A$4:$A$38, 0), $B$5+1) | G22: =IF(F22=0,"",ROUND(50 + 10 * (D22 - E22) / F22, 0)) | H22: =IF(G22="","",IF(G22<35,"Muy bajo",IF(G22<45,"Bajo",IF(G22<=55,"Promedio",IF(G22<=65,"Alto","Muy alto")))))
A23: E2 | B23: Gregariousness | C23: Gregarismo | D23: =SUMPRODUCT((Test!$B$6:$B$125="E2")*IFERROR(VALUE(Test!$G$6:$G$125),0)) | E23: =INDEX(Normas!$B$4:$Q$38, MATCH(A23, Normas!$A$4:$A$38, 0), $B$5) | F23: =INDEX(Normas!$B$4:$Q$38, MATCH(A23, Normas!$A$4:$A$38, 0), $B$5+1) | G23: =IF(F23=0,"",ROUND(50 + 10 * (D23 - E23) / F23, 0)) | H23: =IF(G23="","",IF(G23<35,"Muy bajo",IF(G23<45,"Bajo",IF(G23<=55,"Promedio",IF(G23<=65,"Alto","Muy alto")))))
A24: E3 | B24: Assertiveness | C24: Asertividad | D24: =SUMPRODUCT((Test!$B$6:$B$125="E3")*IFERROR(VALUE(Test!$G$6:$G$125),0)) | E24: =INDEX(Normas!$B$4:$Q$38, MATCH(A24, Normas!$A$4:$A$38, 0), $B$5) | F24: =INDEX(Normas!$B$4:$Q$38, MATCH(A24, Normas!$A$4:$A$38, 0), $B$5+1) | G24: =IF(F24=0,"",ROUND(50 + 10 * (D24 - E24) / F24, 0)) | H24: =IF(G24="","",IF(G24<35,"Muy bajo",IF(G24<45,"Bajo",IF(G24<=55,"Promedio",IF(G24<=65,"Alto","Muy alto")))))
A25: E4 | B25: Activity Level | C25: Actividad | D25: =SUMPRODUCT((Test!$B$6:$B$125="E4")*IFERROR(VALUE(Test!$G$6:$G$125),0)) | E25: =INDEX(Normas!$B$4:$Q$38, MATCH(A25, Normas!$A$4:$A$38, 0), $B$5) | F25: =INDEX(Normas!$B$4:$Q$38, MATCH(A25, Normas!$A$4:$A$38, 0), $B$5+1) | G25: =IF(F25=0,"",ROUND(50 + 10 * (D25 - E25) / F25, 0)) | H25: =IF(G25="","",IF(G25<35,"Muy bajo",IF(G25<45,"Bajo",IF(G25<=55,"Promedio",IF(G25<=65,"Alto","Muy alto")))))
A26: E5 | B26: Excitement-seeking | C26: Búsqueda de emociones | D26: =SUMPRODUCT((Test!$B$6:$B$125="E5")*IFERROR(VALUE(Test!$G$6:$G$125),0)) | E26: =INDEX(Normas!$B$4:$Q$38, MATCH(A26, Normas!$A$4:$A$38, 0), $B$5) | F26: =INDEX(Normas!$B$4:$Q$38, MATCH(A26, Normas!$A$4:$A$38, 0), $B$5+1) | G26: =IF(F26=0,"",ROUND(50 + 10 * (D26 - E26) / F26, 0)) | H26: =IF(G26="","",IF(G26<35,"Muy bajo",IF(G26<45,"Bajo",IF(G26<=55,"Promedio",IF(G26<=65,"Alto","Muy alto")))))
A27: E6 | B27: Cheerfulness | C27: Alegría | D27: =SUMPRODUCT((Test!$B$6:$B$125="E6")*IFERROR(VALUE(Test!$G$6:$G$125),0)) | E27: =INDEX(Normas!$B$4:$Q$38, MATCH(A27, Normas!$A$4:$A$38, 0), $B$5) | F27: =INDEX(Normas!$B$4:$Q$38, MATCH(A27, Normas!$A$4:$A$38, 0), $B$5+1) | G27: =IF(F27=0,"",ROUND(50 + 10 * (D27 - E27) / F27, 0)) | H27: =IF(G27="","",IF(G27<35,"Muy bajo",IF(G27<45,"Bajo",IF(G27<=55,"Promedio",IF(G27<=65,"Alto","Muy alto")))))
A28: O1 | B28: Imagination | C28: Imaginación | D28: =SUMPRODUCT((Test!$B$6:$B$125="O1")*IFERROR(VALUE(Test!$G$6:$G$125),0)) | E28: =INDEX(Normas!$B$4:$Q$38, MATCH(A28, Normas!$A$4:$A$38, 0), $B$5) | F28: =INDEX(Normas!$B$4:$Q$38, MATCH(A28, Normas!$A$4:$A$38, 0), $B$5+1) | G28: =IF(F28=0,"",ROUND(50 + 10 * (D28 - E28) / F28, 0)) | H28: =IF(G28="","",IF(G28<35,"Muy bajo",IF(G28<45,"Bajo",IF(G28<=55,"Promedio",IF(G28<=65,"Alto","Muy alto")))))
A29: O2 | B29: Artistic Interests | C29: Interés artístico | D29: =SUMPRODUCT((Test!$B$6:$B$125="O2")*IFERROR(VALUE(Test!$G$6:$G$125),0)) | E29: =INDEX(Normas!$B$4:$Q$38, MATCH(A29, Normas!$A$4:$A$38, 0), $B$5) | F29: =INDEX(Normas!$B$4:$Q$38, MATCH(A29, Normas!$A$4:$A$38, 0), $B$5+1) | G29: =IF(F29=0,"",ROUND(50 + 10 * (D29 - E29) / F29, 0)) | H29: =IF(G29="","",IF(G29<35,"Muy bajo",IF(G29<45,"Bajo",IF(G29<=55,"Promedio",IF(G29<=65,"Alto","Muy alto")))))
A30: O3 | B30: Emotionality | C30: Emocionalidad | D30: =SUMPRODUCT((Test!$B$6:$B$125="O3")*IFERROR(VALUE(Test!$G$6:$G$125),0)) | E30: =INDEX(Normas!$B$4:$Q$38, MATCH(A30, Normas!$A$4:$A$38, 0), $B$5) | F30: =INDEX(Normas!$B$4:$Q$38, MATCH(A30, Normas!$A$4:$A$38, 0), $B$5+1) | G30: =IF(F30=0,"",ROUND(50 + 10 * (D30 - E30) / F30, 0)) | H30: =IF(G30="","",IF(G30<35,"Muy bajo",IF(G30<45,"Bajo",IF(G30<=55,"Promedio",IF(G30<=65,"Alto","Muy alto")))))
A31: O4 | B31: Adventurousness | C31: Sentido de aventura | D31: =SUMPRODUCT((Test!$B$6:$B$125="O4")*IFERROR(VALUE(Test!$G$6:$G$125),0)) | E31: =INDEX(Normas!$B$4:$Q$38, MATCH(A31, Normas!$A$4:$A$38, 0), $B$5) | F31: =INDEX(Normas!$B$4:$Q$38, MATCH(A31, Normas!$A$4:$A$38, 0), $B$5+1) | G31: =IF(F31=0,"",ROUND(50 + 10 * (D31 - E31) / F31, 0)) | H31: =IF(G31="","",IF(G31<35,"Muy bajo",IF(G31<45,"Bajo",IF(G31<=55,"Promedio",IF(G31<=65,"Alto","Muy alto")))))
A32: O5 | B32: Intellect | C32: Intelecto | D32: =SUMPRODUCT((Test!$B$6:$B$125="O5")*IFERROR(VALUE(Test!$G$6:$G$125),0)) | E32: =INDEX(Normas!$B$4:$Q$38, MATCH(A32, Normas!$A$4:$A$38, 0), $B$5) | F32: =INDEX(Normas!$B$4:$Q$38, MATCH(A32, Normas!$A$4:$A$38, 0), $B$5+1) | G32: =IF(F32=0,"",ROUND(50 + 10 * (D32 - E32) / F32, 0)) | H32: =IF(G32="","",IF(G32<35,"Muy bajo",IF(G32<45,"Bajo",IF(G32<=55,"Promedio",IF(G32<=65,"Alto","Muy alto")))))
A33: O6 | B33: Liberalism | C33: Liberalismo | D33: =SUMPRODUCT((Test!$B$6:$B$125="O6")*IFERROR(VALUE(Test!$G$6:$G$125),0)) | E33: =INDEX(Normas!$B$4:$Q$38, MATCH(A33, Normas!$A$4:$A$38, 0), $B$5) | F33: =INDEX(Normas!$B$4:$Q$38, MATCH(A33, Normas!$A$4:$A$38, 0), $B$5+1) | G33: =IF(F33=0,"",ROUND(50 + 10 * (D33 - E33) / F33, 0)) | H33: =IF(G33="","",IF(G33<35,"Muy bajo",IF(G33<45,"Bajo",IF(G33<=55,"Promedio",IF(G33<=65,"Alto","Muy alto")))))
A34: A1 | B34: Trust | C34: Confianza | D34: =SUMPRODUCT((Test!$B$6:$B$125="A1")*IFERROR(VALUE(Test!$G$6:$G$125),0)) | E34: =INDEX(Normas!$B$4:$Q$38, MATCH(A34, Normas!$A$4:$A$38, 0), $B$5) | F34: =INDEX(Normas!$B$4:$Q$38, MATCH(A34, Normas!$A$4:$A$38, 0), $B$5+1) | G34: =IF(F34=0,"",ROUND(50 + 10 * (D34 - E34) / F34, 0)) | H34: =IF(G34="","",IF(G34<35,"Muy bajo",IF(G34<45,"Bajo",IF(G34<=55,"Promedio",IF(G34<=65,"Alto","Muy alto")))))
A35: A2 | B35: Morality | C35: Moralidad | D35: =SUMPRODUCT((Test!$B$6:$B$125="A2")*IFERROR(VALUE(Test!$G$6:$G$125),0)) | E35: =INDEX(Normas!$B$4:$Q$38, MATCH(A35, Normas!$A$4:$A$38, 0), $B$5) | F35: =INDEX(Normas!$B$4:$Q$38, MATCH(A35, Normas!$A$4:$A$38, 0), $B$5+1) | G35: =IF(F35=0,"",ROUND(50 + 10 * (D35 - E35) / F35, 0)) | H35: =IF(G35="","",IF(G35<35,"Muy bajo",IF(G35<45,"Bajo",IF(G35<=55,"Promedio",IF(G35<=65,"Alto","Muy alto")))))
A36: A3 | B36: Altruism | C36: Altruismo | D36: =SUMPRODUCT((Test!$B$6:$B$125="A3")*IFERROR(VALUE(Test!$G$6:$G$125),0)) | E36: =INDEX(Normas!$B$4:$Q$38, MATCH(A36, Normas!$A$4:$A$38, 0), $B$5) | F36: =INDEX(Normas!$B$4:$Q$38, MATCH(A36, Normas!$A$4:$A$38, 0), $B$5+1) | G36: =IF(F36=0,"",ROUND(50 + 10 * (D36 - E36) / F36, 0)) | H36: =IF(G36="","",IF(G36<35,"Muy bajo",IF(G36<45,"Bajo",IF(G36<=55,"Promedio",IF(G36<=65,"Alto","Muy alto")))))
A37: A4 | B37: Cooperation | C37: Cooperación | D37: =SUMPRODUCT((Test!$B$6:$B$125="A4")*IFERROR(VALUE(Test!$G$6:$G$125),0)) | E37: =INDEX(Normas!$B$4:$Q$38, MATCH(A37, Normas!$A$4:$A$38, 0), $B$5) | F37: =INDEX(Normas!$B$4:$Q$38, MATCH(A37, Normas!$A$4:$A$38, 0), $B$5+1) | G37: =IF(F37=0,"",ROUND(50 + 10 * (D37 - E37) / F37, 0)) | H37: =IF(G37="","",IF(G37<35,"Muy bajo",IF(G37<45,"Bajo",IF(G37<=55,"Promedio",IF(G37<=65,"Alto","Muy alto")))))
A38: A5 | B38: Modesty | C38: Modestia | D38: =SUMPRODUCT((Test!$B$6:$B$125="A5")*IFERROR(VALUE(Test!$G$6:$G$125),0)) | E38: =INDEX(Normas!$B$4:$Q$38, MATCH(A38, Normas!$A$4:$A$38, 0), $B$5) | F38: =INDEX(Normas!$B$4:$Q$38, MATCH(A38, Normas!$A$4:$A$38, 0), $B$5+1) | G38: =IF(F38=0,"",ROUND(50 + 10 * (D38 - E38) / F38, 0)) | H38: =IF(G38="","",IF(G38<35,"Muy bajo",IF(G38<45,"Bajo",IF(G38<=55,"Promedio",IF(G38<=65,"Alto","Muy alto")))))
A39: A6 | B39: Sympathy | C39: Simpatía | D39: =SUMPRODUCT((Test!$B$6:$B$125="A6")*IFERROR(VALUE(Test!$G$6:$G$125),0)) | E39: =INDEX(Normas!$B$4:$Q$38, MATCH(A39, Normas!$A$4:$A$38, 0), $B$5) | F39: =INDEX(Normas!$B$4:$Q$38, MATCH(A39, Normas!$A$4:$A$38, 0), $B$5+1) | G39: =IF(F39=0,"",ROUND(50 + 10 * (D39 - E39) / F39, 0)) | H39: =IF(G39="","",IF(G39<35,"Muy bajo",IF(G39<45,"Bajo",IF(G39<=55,"Promedio",IF(G39<=65,"Alto","Muy alto")))))
A40: C1 | B40: Self-efficacy | C40: Autoeficacia | D40: =SUMPRODUCT((Test!$B$6:$B$125="C1")*IFERROR(VALUE(Test!$G$6:$G$125),0)) | E40: =INDEX(Normas!$B$4:$Q$38, MATCH(A40, Normas!$A$4:$A$38, 0), $B$5) | F40: =INDEX(Normas!$B$4:$Q$38, MATCH(A40, Normas!$A$4:$A$38, 0), $B$5+1) | G40: =IF(F40=0,"",ROUND(50 + 10 * (D40 - E40) / F40, 0)) | H40: =IF(G40="","",IF(G40<35,"Muy bajo",IF(G40<45,"Bajo",IF(G40<=55,"Promedio",IF(G40<=65,"Alto","Muy alto")))))
A41: C2 | B41: Orderliness | C41: Orden | D41: =SUMPRODUCT((Test!$B$6:$B$125="C2")*IFERROR(VALUE(Test!$G$6:$G$125),0)) | E41: =INDEX(Normas!$B$4:$Q$38, MATCH(A41, Normas!$A$4:$A$38, 0), $B$5) | F41: =INDEX(Normas!$B$4:$Q$38, MATCH(A41, Normas!$A$4:$A$38, 0), $B$5+1) | G41: =IF(F41=0,"",ROUND(50 + 10 * (D41 - E41) / F41, 0)) | H41: =IF(G41="","",IF(G41<35,"Muy bajo",IF(G41<45,"Bajo",IF(G41<=55,"Promedio",IF(G41<=65,"Alto","Muy alto")))))
A42: C3 | B42: Dutifulness | C42: Sentido del deber | D42: =SUMPRODUCT((Test!$B$6:$B$125="C3")*IFERROR(VALUE(Test!$G$6:$G$125),0)) | E42: =INDEX(Normas!$B$4:$Q$38, MATCH(A42, Normas!$A$4:$A$38, 0), $B$5) | F42: =INDEX(Normas!$B$4:$Q$38, MATCH(A42, Normas!$A$4:$A$38, 0), $B$5+1) | G42: =IF(F42=0,"",ROUND(50 + 10 * (D42 - E42) / F42, 0)) | H42: =IF(G42="","",IF(G42<35,"Muy bajo",IF(G42<45,"Bajo",IF(G42<=55,"Promedio",IF(G42<=65,"Alto","Muy alto")))))
A43: C4 | B43: Achievement-striving | C43: Búsqueda de logro | D43: =SUMPRODUCT((Test!$B$6:$B$125="C4")*IFERROR(VALUE(Test!$G$6:$G$125),0)) | E43: =INDEX(Normas!$B$4:$Q$38, MATCH(A43, Normas!$A$4:$A$38, 0), $B$5) | F43: =INDEX(Normas!$B$4:$Q$38, MATCH(A43, Normas!$A$4:$A$38, 0), $B$5+1) | G43: =IF(F43=0,"",ROUND(50 + 10 * (D43 - E43) / F43, 0)) | H43: =IF(G43="","",IF(G43<35,"Muy bajo",IF(G43<45,"Bajo",IF(G43<=55,"Promedio",IF(G43<=65,"Alto","Muy alto")))))
...

Sheet Perfil
A1: Perfil
A3: Dominios (puntuaciones T)
A5: Dominio | B5: T
A6: Neuroticismo | B6: =IFERROR(Resultados!G9,"")
A7: Extraversión | B7: =IFERROR(Resultados!G10,"")
A8: Apertura | B8: =IFERROR(Resultados!G11,"")
A9: Amabilidad | B9: =IFERROR(Resultados!G12,"")
A10: Responsabilidad | B10: =IFERROR(Resultados!G13,"")
A22: Facetas (puntuaciones T)
A24: Faceta | B24: T
A25: N1 · Ansiedad | B25: =IFERROR(Resultados!G16,"")
A26: N2 · Ira | B26: =IFERROR(Resultados!G17,"")
A27: N3 · Depresión | B27: =IFERROR(Resultados!G18,"")
A28: N4 · Autoconciencia | B28: =IFERROR(Resultados!G19,"")
A29: N5 · Inmoderación | B29: =IFERROR(Resultados!G20,"")
A30: N6 · Vulnerabilidad | B30: =IFERROR(Resultados!G21,"")
A31: E1 · Amabilidad social | B31: =IFERROR(Resultados!G22,"")
A32: E2 · Gregarismo | B32: =IFERROR(Resultados!G23,"")
A33: E3 · Asertividad | B33: =IFERROR(Resultados!G24,"")
A34: E4 · Actividad | B34: =IFERROR(Resultados!G25,"")
A35: E5 · Búsqueda de emociones | B35: =IFERROR(Resultados!G26,"")
A36: E6 · Alegría | B36: =IFERROR(Resultados!G27,"")
... A54: C6 · Cautela | B54: =IFERROR(Resultados!G45,"")

Sheet Dominios
A1: Dominios
A3: Código | B3: Nombre | C3: T | D3: Nivel | E3: Descripción
A4: N | B4: Neuroticismo | C4: =IFERROR(Resultados!G9,"") | D4: =IFERROR(Resultados!H9,"") | E4: Refleja la tendencia a experimentar emociones negativas (ansiedad, tristeza, irritabilidad). Alto: reactivo emocionalmente, sensible al estrés. Bajo: estable, sereno, resistente.
A5: E | B5: Extraversión | C5: =IFERROR(Resultados!G10,"") | D5: =IFERROR(Resultados!H10,"") | E5: Refleja el nivel de energía social, entusiasmo y búsqueda de estimulación. Alto: sociable, expresivo, activo. Bajo: reservado, tranquilo, prefiere la soledad.
A6: O | B6: Apertura | C6: =IFERROR(Resultados!G11,"") | D6: =IFERROR(Resultados!H11,"") | E6: Refleja apertura a nuevas ideas, arte, sentimientos y experiencias. Alto: curioso, imaginativo, no convencional. Bajo: pragmático, tradicional, concreto.
A7: A | B7: Amabilidad | C7: =IFERROR(Resultados!G12,"") | D7: =IFERROR(Resultados!H12,"") | E7: Refleja la orientación cooperativa y confiada hacia los demás. Alto: empático, generoso, buscando armonía. Bajo: escéptico, competitivo, directo.
A8: C | B8: Responsabilidad | C8: =IFERROR(Resultados!G13,"") | D8: =IFERROR(Resultados!H13,"") | E8: Refleja autocontrol, organización y orientación a metas. Alto: metódico, responsable, disciplinado. Bajo: espontáneo, flexible, tolerante al desorden.

Sheet Facetas
A1: Facetas
A3: Dominio | B3: Código | C3: Nombre | D3: T | E3: Nivel | F3: Descripción
A4: Neuroticismo | B4: N1 | C4: Ansiedad | D4: =IFERROR(Resultados!G16,"") | E4: =IFERROR(Resultados!H16,"") | F4: Preocupación y tensión frente a lo incierto.
A5: Neuroticismo | B5: N2 | C5: Ira | D5: =IFERROR(Resultados!G17,"") | E5: =IFERROR(Resultados!H17,"") | F5: Facilidad para enojarse ante frustraciones.
A6: Neuroticismo | B6: N3 | C6: Depresión | D6: =IFERROR(Resultados!G18,"") | E6: =IFERROR(Resultados!H18,"") | F6: Tendencia a tristeza, culpa y desánimo.
A7: Neuroticismo | B7: N4 | C7: Autoconciencia | D7: =IFERROR(Resultados!G19,"") | E7: =IFERROR(Resultados!H19,"") | F7: Timidez o incomodidad ante la mirada ajena.
A8: Neuroticismo | B8: N5 | C8: Inmoderación | D8: =IFERROR(Resultados!G20,"") | E8: =IFERROR(Resultados!H20,"") | F8: Dificultad para resistir impulsos y antojos.
A9: Neuroticismo | B9: N6 | C9: Vulnerabilidad | D9: =IFERROR(Resultados!G21,"") | E9: =IFERROR(Resultados!H21,"") | F9: Sentirse abrumado en momentos de crisis.
A10: Extraversión | B10: E1 | C10: Amabilidad social | D10: =IFERROR(Resultados!G22,"") | E10: =IFERROR(Resultados!H22,"") | F10: Interés genuino por otras personas; calidez.
A11: Extraversión | B11: E2 | C11: Gregarismo | D11: =IFERROR(Resultados!G23,"") | E11: =IFERROR(Resultados!H23,"") | F11: Preferencia por compañía sobre soledad.
A12: Extraversión | B12: E3 | C12: Asertividad | D12: =IFERROR(Resultados!G24,"") | E12: =IFERROR(Resultados!H24,"") | F12: Facilidad para liderar y expresar opiniones.
A13: Extraversión | B13: E4 | C13: Actividad | D13: =IFERROR(Resultados!G25,"") | E13: =IFERROR(Resultados!H25,"") | F13: Ritmo de vida enérgico y ocupado.
A14: Extraversión | B14: E5 | C14: Búsqueda de emociones | D14: =IFERROR(Resultados!G26,"") | E14: =IFERROR(Resultados!H26,"") | F14: Gusto por el riesgo, novedad y estimulación fuerte.
A15: Extraversión | B15: E6 | C15: Alegría | D15: =IFERROR(Resultados!G27,"") | E15: =IFERROR(Resultados!H27,"") | F15: Capacidad de disfrutar alegre y espontáneamente.
... A33: Responsabilidad | B33: C6 | C33: Cautela | D33: =IFERROR(Resultados!G45,"") | E33: =IFERROR(Resultados!H45,"") | F33: Reflexión antes de actuar; evitación del riesgo.

Sheet Glosario
A1: Glosario
A3: Término | B3: Definición
A4: Big Five | B4: Modelo de personalidad de Cinco Grandes: N, E, O, A, C. Consenso empírico dominante desde los 90s.
A5: Dominio | B5: Rasgo amplio (uno de los 5). Cada dominio agrega la información de 6 facetas.
A6: Faceta | B6: Subrasgo específico dentro de un dominio (30 en total).
A7: Ítem | B7: Frase corta a la que respondes 1-5. Hay 120.
A8: Escala Likert | B8: Formato de respuesta con opciones ordenadas de acuerdo/desacuerdo, aquí de 1 a 5.
A9: Clave F (forward) | B9: Ítem cuya respuesta se puntúa directamente (1→1, 5→5).
A10: Clave R (reverse) | B10: Ítem cuya respuesta se invierte (1→5, 5→1) porque está redactado en sentido opuesto al rasgo.
A11: Puntuación bruta | B11: Suma de respuestas puntuadas para una escala. Faceta: 4-20. Dominio: 24-120.
A12: Puntuación T | B12: Puntuación estandarizada con media 50 y DE 10. Permite comparar contra la población normativa.
A13: Norma | B13: Media y DE de referencia calculadas en una muestra grande, segmentada por sexo y edad.
A14: Grupo normativo | B14: Combinación Sexo × Rango de edad usada para estandarizar tus puntuaciones brutas.
... A22: Autoinforme | B22: Datos obtenidos preguntándole al propio sujeto, no observados desde afuera.

Sheet Acerca
B2: Acerca de este documento
B4: Ítems (inglés)
B5: Tomados del International Personality Item Pool (IPIP) — http://ipip.ori.org — dominio público.
B6: Selección y ordenamiento de los 120 ítems: John A. Johnson (2014).
B8: Puntuación y normas
B9: Johnson, J. A. (2014). Measuring thirty facets of the Five Factor Model with a 120-item
B10: public domain inventory: Development of the IPIP-NEO-120. Journal of Research in
B11: Personality, 51, 78-89.
B12: Materiales originales y normas: OSF project tbmh5.
B14: Traducción al español
B15: Traducción NO OFICIAL — hecha para uso personal. La columna en inglés es siempre
B16: el texto autoritativo. Existe una versión validada al español argentino (Cupani et al.)
... B34: 10 hojas: Portada · Instrucciones · Test · Normas · Resultados · Perfil · Dominios · Facetas · Glosario · Acerca
