Workbook

Sheet Respuestas
E1: CORRECCIÓN MECANIZADA DEL MMPI - 2
C2: Nombre: | D2: Ivan
C3: Edad: | N3: RECUERDA: 1- VERDADERO; 2 - FALSO; 3 - EN BLANCO
C4: Fecha:
C5: Evaluador:
C7: ITEM | D7: RESP | E7: ITEM | F7: RESP | G7: ITEM | H7: RESP | I7: ITEM | J7: RESP | K7: ITEM | L7: RESP | M7: ITEM | N7: RESP | O7: ITEM | P7: RESP | Q7: ITEM | R7: RESP | S7: ITEM | T7: RESP | U7: ITEM | V7: RESP
C8: 1 | E8: 61 | G8: 121 | I8: 181 | K8: 241 | M8: 301 | O8: 361 | Q8: 421 | S8: 481 | U8: 541
C9: 2 | E9: 62 | G9: 122 | I9: 182 | K9: 242 | M9: 302 | O9: 362 | Q9: 422 | S9: 482 | U9: 542
C10: 3 | E10: 63 | G10: 123 | I10: 183 | K10: 243 | M10: 303 | O10: 363 | Q10: 423 | S10: 483 | U10: 543
C11: 4 | E11: 64 | G11: 124 | I11: 184 | K11: 244 | M11: 304 | O11: 364 | Q11: 424 | S11: 484 | U11: 544
C12: 5 | E12: 65 | G12: 125 | I12: 185 | K12: 245 | M12: 305 | O12: 365 | Q12: 425 | S12: 485 | U12: 545
C13: 6 | E13: 66 | G13: 126 | I13: 186 | K13: 246 | M13: 306 | O13: 366 | Q13: 426 | S13: 486 | U13: 546
C14: 7 | E14: 67 | G14: 127 | I14: 187 | K14: 247 | M14: 307 | O14: 367 | Q14: 427 | S14: 487 | U14: 547
C15: 8 | E15: 68 | G15: 128 | I15: 188 | K15: 248 | M15: 308 | O15: 368 | Q15: 428 | S15: 488 | U15: 548
C16: 9 | E16: 69 | G16: 129 | I16: 189 | K16: 249 | M16: 309 | O16: 369 | Q16: 429 | S16: 489 | U16: 549
C17: 10 | E17: 70 | G17: 130 | I17: 190 | K17: 250 | M17: 310 | O17: 370 | Q17: 430 | S17: 490 | U17: 550
C18: 11 | E18: 71 | G18: 131 | I18: 191 | K18: 251 | M18: 311 | O18: 371 | Q18: 431 | S18: 491 | U18: 551
C19: 12 | E19: 72 | G19: 132 | I19: 192 | K19: 252 | M19: 312 | O19: 372 | Q19: 432 | S19: 492 | U19: 552
... C34: 27 | E34: 87 | G34: 147 | I34: 207 | K34: 267 | M34: 327 | O34: 387 | Q34: 447 | S34: 507 | U34: 567
C35: 28 | E35: 88 | G35: 148 | I35: 208 | K35: 268 | M35: 328 | O35: 388 | Q35: 448 | S35: 508
C36: 29 | E36: 89 | G36: 149 | I36: 209 | K36: 269 | M36: 329 | O36: 389 | Q36: 449 | S36: 509
C37: 30 | E37: 90 | G37: 150 | I37: 210 | K37: 270 | M37: 330 | O37: 390 | Q37: 450 | S37: 510
C38: 31 | E38: 91 | G38: 151 | I38: 211 | K38: 271 | M38: 331 | O38: 391 | Q38: 451 | S38: 511
C39: 32 | E39: 92 | G39: 152 | I39: 212 | K39: 272 | M39: 332 | O39: 392 | Q39: 452 | S39: 512
C40: 33 | E40: 93 | G40: 153 | I40: 213 | K40: 273 | M40: 333 | O40: 393 | Q40: 453 | S40: 513
C41: 34 | E41: 94 | G41: 154 | I41: 214 | K41: 274 | M41: 334 | O41: 394 | Q41: 454 | S41: 514
C42: 35 | E42: 95 | G42: 155 | I42: 215 | K42: 275 | M42: 335 | O42: 395 | Q42: 455 | S42: 515
C43: 36 | E43: 96 | G43: 156 | I43: 216 | K43: 276 | M43: 336 | O43: 396 | Q43: 456 | S43: 516
C44: 37 | E44: 97 | G44: 157 | I44: 217 | K44: 277 | M44: 337 | O44: 397 | Q44: 457 | S44: 517
C45: 38 | E45: 98 | G45: 158 | I45: 218 | K45: 278 | M45: 338 | O45: 398 | Q45: 458 | S45: 518
C46: 39 | E46: 99 | G46: 159 | I46: 219 | K46: 279 | M46: 339 | O46: 399 | Q46: 459 | S46: 519
... C67: 60 | E67: 120 | G67: 180 | I67: 240 | K67: 300 | M67: 360 | O67: 420 | Q67: 480 | S67: 540
C71: Escalas de validación | U71: S.P. | V71: P.D. | W71: FRAC. K | X71: P.CORR. | Y71: P.DIRECTAS | Z71: P.TIPICAS
C72: ? | D72: =COUNTIF(D8:D67,"=3") | F72: =COUNTIF(F8:F67,"=3") | H72: =COUNTIF(H8:H67,"=3") | L72: =COUNTIF(L8:L67,"=3") | N72: =COUNTIF(N8:N67,"=3") | P72: =COUNTIF(P8:P67,"=3") | R72: =COUNTIF(R8:R67,"=3") | S72: =COUNTIF(T8:T67,"=3") | T72: =COUNTIF(V8:V67,"=3") | V72: =SUM(D72:T72) | Y72: =SUM(V72) | Z72: =IF(D154<>0,D154,IF(E154<>0,E154,IF(F154<>0,F154,IF(G154<>0,G154,IF(H154<>0,H154,0)))))
C73: L | D73: =IF(D23=1,0,IF(D23=2,1,0)) | E73: =IF(D36=1,0,IF(D36=2,1,0)) | F73: =IF(D48=1,0,IF(D48=2,1,0)) | G73: =IF(D58=1,0,IF(D58=2,1,0)) | H73: =IF(F24=1,0,IF(F24=2,1,0)) | I73: =IF(F40=1,0,IF(F40=2,1,0)) | J73: =IF(F49=1,0,IF(F49=2,1,0)) | K73: =IF(F54=1,0,IF(F54=2,1,0)) | L73: =IF(H10=1,0,IF(H10=2,1,0)) | M73: =IF(H26=1,0,IF(H26=2,1,0)) | N73: =IF(H40=1,0,IF(H40=2,1,0)) | O73: =IF(J10=1,0,IF(J10=2,1,0)) | P73: =IF(J30=1,0,IF(J30=2,1,0)) | Q73: =IF(J59=1,0,IF(J59=2,1,0)) | R73: =IF(L27=1,0,IF(L27=2,1,0)) | V73: =SUM(D73:R73) | Y73: =SUM(V73) | Z73: =IF(D155<>0,D155,IF(E155<>0,E155,IF(F155<>0,F155)))
C74: F | D74: =IF(D13=1,0,IF(D13=2,1,0)) | E74: =IF(D19=1,0,IF(D19=2,1,0)) | F74: =IF(D25=1,1,IF(D25=2,0,0)) | G74: =IF(D31=1,1,IF(D31=2,0,0)) | H74: =IF(D37=1,1,IF(D37=2,0,0)) | I74: =IF(D43=1,1,IF(D43=2,0,0)) | J74: =IF(D49=1,1,IF(D49=2,0,0)) | K74: =IF(D55=1,1,IF(D55=2,0,0)) | L74: =IF(D61=1,1,IF(D61=2,0,0)) | M74: =IF(D67=1,1,IF(D67=2,0,0)) | N74: =IF(F13=1,1,IF(F13=2,0,0)) | O74: =IF(F19=1,1,IF(F19=2,0,0)) | P74: =IF(F25=1,0,IF(F25=2,1,0)) | Q74: =IF(F31=1,1,IF(F31=2,0,0)) | R74: =IF(F37=1,0,IF(F37=2,1,0)) | S74: =IF(F43=1,1,IF(F43=2,0,0)) | T74: =IF(F49=1,0,IF(F49=2,1,0)) | U74: =SUM(D74:T74)
D75: =IF(F55=1,0,IF(F55=2,1,0)) | E75: =IF(F61=1,1,IF(F61=2,0,0)) | F75: =IF(F67=1,0,IF(F67=2,1,0)) | G75: =IF(H13=1,0,IF(H13=2,1,0)) | H75: =IF(H19=1,0,IF(H19=2,1,0)) | I75: =IF(H25=1,1,IF(H25=2,0,0)) | J75: =IF(H31=1,1,IF(H31=2,0,0)) | K75: =IF(H37=1,1,IF(H37=2,0,0)) | L75: =IF(H43=1,1,IF(H43=2,0,0)) | M75: =IF(H49=1,1,IF(H49=2,0,0)) | N75: =IF(H55=1,1,IF(H55=2,0,0)) | O75: =IF(H61=1,0,IF(H61=2,1,0)) | P75: =IF(H67=1,1,IF(H67=2,0,0)) | Q75: =IF(J13=1,0,IF(J13=2,1,0)) | R75: =IF(J19=1,0,IF(J19=2,1,0)) | S75: =IF(J25=1,1,IF(J25=2,0,0)) | T75: =IF(J31=1,0,IF(J31=2,1,0)) | U75: =SUM(D75:T75)
D76: =IF(J37=1,0,IF(J37=2,1,0)) | E76: =IF(J43=1,1,IF(J43=2,0,0)) | F76: =IF(J49=1,0,IF(J48=2,1,0)) | G76: =IF(J55=1,1,IF(J55=2,0,0)) | H76: =IF(J61=1,1,IF(J61=2,0,0)) | I76: =IF(J67=1,1,IF(J67=2,0,0)) | J76: =IF(L13=1,1,IF(L43=2,0,0)) | K76: =IF(L19=1,1,IF(L19=2,0,0)) | L76: =IF(L25=1,1,IF(L25=2,0,0)) | M76: =IF(L31=1,1,IF(L31=2,0,0)) | N76: =IF(L37=1,1,IF(L37=2,0,0)) | O76: =IF(L43=1,0,IF(L43=2,1,0)) | P76: =IF(L49=1,1,IF(L49=2,0,0)) | Q76: =IF(L55=1,1,IF(L55=2,0,0)) | R76: =IF(L61=1,1,IF(L61=2,0,0)) | S76: =IF(L67=1,1,IF(L67=2,0,0)) | T76: =IF(N13=1,1,IF(N13=2,0,0)) | U76: =SUM(D76:T76)
D77: =IF(N19=1,1,IF(N19=2,0,0)) | E77: =IF(N25=1,0,IF(N25=2,0,0)) | F77: =IF(N31=1,1,IF(N31=2,0,0)) | G77: =IF(N37=1,0,IF(N37=2,1,0)) | H77: =IF(N43=1,1,IF(N43=2,0,0)) | I77: =IF(N50=1,0,IF(N50=2,1,0)) | J77: =IF(N56=1,1,IF(N56=2,0,0)) | K77: =IF(N62=1,1,IF(N62=2,0,0)) | L77: =IF(P8=1,1,IF(P8=2,0,0)) | U77: =SUM(D77:T77) | V77: =SUM(U74:U77) | Y77: =SUM(V77) | Z77: =IF(D156<>0,D156,IF(E156<>0,E156,IF(F156<>0,F156,IF(G156<>0,G156,IF(H156<>0,H156,IF(I156<>0,I156,IF(J156<>0,J156,0)))))))
C78: K | D78: =IF(D36=1,0,IF(D36=2,1,0)) | E78: =IF(D44=1,0,IF(D44=2,1,0)) | F78: =IF(D65=1,0,IF(D65=2,1,0)) | G78: =IF(F23=1,0,IF(F23=2,1,0)) | H78: =IF(F30=1,1,IF(F30=2,0,0)) | I78: =IF(F57=1,0,IF(F57=2,1,0)) | J78: =IF(F63=1,0,IF(F63=2,1,0)) | K78: =IF(H9=1,0,IF(H9=2,1,0)) | L78: =IF(H14=1,0,IF(H14=2,1,0)) | M78: =IF(H17=1,0,IF(H17=2,1,0)) | N78: =IF(H23=1,0,IF(H23=2,1,0)) | O78: =IF(H35=1,0,IF(H35=2,1,0)) | P78: =IF(H44=1,0,IF(H44=2,1,0)) | Q78: =IF(H45=1,0,IF(H45=2,1,0)) | R78: =IF(H54=1,0,IF(H54=2,1,0)) | S78: =IF(H58=1,0,IF(H58=2,1,0)) | T78: =IF(J23=1,0,IF(J23=2,1,0)) | U78: =SUM(D78:T78)
...

Sheet Sheet1

Sheet Informe
D2: MMPI - 2 | J2: MMPI - 2
B4: Cliente: | I4: Cliente:
B5: Edad: | I5: Edad:
B6: Fecha: | I6: Fecha:
B7: Evaluador: | I7: Evaluador:
E8: Usar estos | F8: NO USAR | G8: ESTOS
E9: datos | F9: DATOS | I9: SUBESCALAS de Harry - Lingoes
B10: ESCALAS DE VALIDEZ | E10: P.Directas | F10: P.D.+ K | G10: P.Típicas | I10: DEPRESIÓN | M10: P. Directas | N10: P. Típicas
B11: ? (Interrogantes) | E11: =Respuestas!V72 | F11: =Respuestas!Y72 | G11: =Respuestas!Z72 | I11: D1: Depresión subjetiva | M11: =Respuestas!X372 | N11: =Respuestas!P374
B12: L (Mentira) | E12: =Respuestas!V73 | F12: =Respuestas!Y73 | G12: =Respuestas!Z73 | I12: D2: Retardo Psicomotor | M12: =Respuestas!X376 | N12: =Respuestas!P378
B13: F (Incoherencia) | E13: =Respuestas!V77 | F13: =Respuestas!Y77 | G13: =Respuestas!Z77 | I13: D3: Problemas Físicos | M13: =Respuestas!X380 | N13: =Respuestas!P382
B14: K (Corrección) | E14: =Respuestas!V79 | F14: =Respuestas!Y79 | G14: =Respuestas!Z79 | I14: D4: Inhibición mental. | M14: =Respuestas!X384 | N14: =Respuestas!P386
B15: ESCALAS CLINICAS O BÁSICAS | I15: D5: Rumiación | M15: =Respuestas!X388 | N15: =Respuestas!P390
B16: Hs (Hipocondría) | E16: =Respuestas!V82 | F16: =Respuestas!Y82 | G16: =Respuestas!Z82
B17: D (Depresión) | E17: =Respuestas!V86 | F17: =Respuestas!Y86 | G17: =Respuestas!Z86 | I17: HISTERIA
B18: Hy (Histeria de conversión) | E18: =Respuestas!V90 | F18: =Respuestas!Y90 | G18: =Respuestas!Z90 | I18: Hy1: Negación de la ansiedad social | M18: =Respuestas!X394 | N18: =Respuestas!P396
B19: Pd (Desviación psicopática) | E19: =Respuestas!V93 | F19: =Respuestas!Y93 | G19: =Respuestas!Z93 | I19: Hy2: Necesidad de afecto | M19: =Respuestas!X398 | N19: =Respuestas!P400
B20: Mfv (Masculinidad) | E20: =Respuestas!V97 | F20: =Respuestas!Y97 | G20: =Respuestas!Z97 | I20: Hy3: Lasitud-enfermedad | M20: =Respuestas!X402 | N20: =Respuestas!P404
B21: Pa (Paranoia) | E21: =Respuestas!V104 | F21: =Respuestas!Y104 | G21: =Respuestas!Z104 | I21: Hy4: Quejas somáticas. | M21: =Respuestas!X406 | N21: =Respuestas!P408
B22: Pt (Psicastenia) | E22: =Respuestas!V107 | F22: =Respuestas!Y107 | G22: =Respuestas!Z107 | I22: Hy5: Inhibición de la agresión | M22: =Respuestas!X410 | N22: =Respuestas!P412
B23: Sc (Esquizofrenia) | E23: =Respuestas!V112 | F23: =Respuestas!Y112 | G23: =Respuestas!Z112
B24: Ma (Hipomanía) | E24: =Respuestas!V115 | F24: =Respuestas!Y115 | G24: =Respuestas!Z115 | I24: DESVIACIÓN PSICOPÁTICA
B25: Si (Introversión social) | E25: =Respuestas!V120 | F25: =Respuestas!Y120 | G25: =Respuestas!Z120 | I25: Pd1: Discordia familiar | M25: =Respuestas!X416 | N25: =Respuestas!P418
B26: ESCALAS DE CONTENIDO | I26: Pd2: Problemas con las figuras de autoridad | M26: =Respuestas!X420 | N26: =Respuestas!P422
B27: ANX (Ansiedad) | E27: =Respuestas!V123 | F27: =Respuestas!Y123 | G27: =Respuestas!Z123 | I27: Pd3: Imperturbabilidad Social | M27: =Respuestas!X424 | N27: =Respuestas!P426
B28: FRS (Miedos) | E28: =Respuestas!V125 | F28: =Respuestas!Y125 | G28: =Respuestas!Z125 | I28: Pd4: Alienación social | M28: =Respuestas!X428 | N28: =Respuestas!P430
B29: OBS (Obsesividad) | E29: =Respuestas!V126 | F29: =Respuestas!Y126 | G29: =Respuestas!Z126 | I29: Pd5: Autoalienación | M29: =Respuestas!X432 | N29: =Respuestas!P434
B30: DEP (Depresión) | E30: =Respuestas!V128 | F30: =Respuestas!Y128 | G30: =Respuestas!Z128
B31: HEA (Preocupaciones por la salud) | E31: =Respuestas!V131 | F31: =Respuestas!Y131 | G31: =Respuestas!Z131 | I31: PARANOIA
B32: BIZ (Pensamiento estrafalario) | E32: =Respuestas!V133 | F32: =Respuestas!Y133 | G32: =Respuestas!Z133 | I32: Pa1: Ideas persecutorias | M32: =Respuestas!X438 | N32: =Respuestas!P440
B33: ANG (Hostilidad) | E33: =Respuestas!V134 | F33: =Respuestas!Y134 | G33: =Respuestas!Z134 | I33: Pa2: Hiperestesia | M33: =Respuestas!X442 | N33: =Respuestas!P444
B34: CYN (Cinismo) | E34: =Respuestas!V136 | F34: =Respuestas!Y136 | G34: =Respuestas!Z136 | I34: Pa3: Ingenuidad | M34: =Respuestas!X446 | N34: =Respuestas!P448
B35: ASP (Conductas antisociales) | E35: =Respuestas!V138 | F35: =Respuestas!Y138 | G35: =Respuestas!Z138
B36: TPA (Comportamiento tipo A) | E36: =Respuestas!V140 | F36: =Respuestas!Y140 | G36: =Respuestas!Z140 | I36: ESQUIZOFRENIA
B37: LSE (Baja autoestima) | E37: =Respuestas!V142 | F37: =Respuestas!Y142 | G37: =Respuestas!Z142 | I37: Sc1: Alienación social | M37: =Respuestas!X453 | N37: =Respuestas!P455
B38: SOD (Malestar social) | E38: =Respuestas!V144 | F38: =Respuestas!Y144 | G38: =Respuestas!Z144 | I38: Sc2: Alienación emocional | M38: =Respuestas!X457 | N38: =Respuestas!P459
B39: FAM (Problemas familiares) | E39: =Respuestas!V146 | F39: =Respuestas!Y146 | G39: =Respuestas!Z146 | I39: Sc3: Ausencia de control del yo, cognitivo | M39: =Respuestas!X461 | N39: =Respuestas!P463
B40: WRK (Interferencia laboral) | E40: =Respuestas!V148 | F40: =Respuestas!Y148 | G40: =Respuestas!Z148 | I40: Sc4: Ausencia del control del yo, conativo | M40: =Respuestas!X465 | N40: =Respuestas!P467
B41: TRT(Indicadores negativos de tratam.) | E41: =Respuestas!V150 | F41: =Respuestas!Y150 | G41: =Respuestas!Z150 | I41: Sc5: Ausencia del control del yo, inhibición defectual | M41: =Respuestas!X469 | N41: =Respuestas!P471
I42: Sc6: Experiencias sensoriales bizarras. | M42: =Respuestas!X474 | N42: =Respuestas!P476
...

Sheet Interpretación
C2: MMPI - 2
B3: Cliente:
B4: Fecha:
B5: Evaluador:
C7: INTERPRETACIÓN
B9: Escalas de Validación:
B10: L | C10: =Respuestas!I188
B13: F | C13: =Respuestas!P189
B16: K | C16: =Respuestas!H190
B20: Valoración Clínica:
B21: Escalas de Validación:
B22: L | C22: =Respuestas!I193
B25: F | C25: =Respuestas!N194
B28: K | C28: =Respuestas!H195
B32: Escalas Clínicas Básicas:
B33: Hs | C33: =Respuestas!N197
B36: D | C36: =Respuestas!J198
B39: Hy | C39: =Respuestas!K199
B42: Pd | C42: =Respuestas!K200
B45: Mf | C45: =Respuestas!K201
B48: Pa | C48: =Respuestas!J202
B51: Pt | C51: =Respuestas!K203
B54: Sc | C54: =Respuestas!J204
B57: Ma | C57: =Respuestas!K205
B60: Si | C60: =Respuestas!K206
C63: JIRS
D67: Fdo.
